[2024-09-22T10:18:07.787+0000] {taskinstance.py:1157} INFO - Dependencies all met for dep_context=non-requeueable deps ti=<TaskInstance: flats.get_coords manual__2024-09-22T10:17:18.922906+00:00 [queued]>
[2024-09-22T10:18:07.813+0000] {taskinstance.py:1157} INFO - Dependencies all met for dep_context=requeueable deps ti=<TaskInstance: flats.get_coords manual__2024-09-22T10:17:18.922906+00:00 [queued]>
[2024-09-22T10:18:07.813+0000] {taskinstance.py:1359} INFO - Starting attempt 1 of 1
[2024-09-22T10:18:07.835+0000] {taskinstance.py:1380} INFO - Executing <Task(PythonOperator): get_coords> on 2024-09-22 10:17:18.922906+00:00
[2024-09-22T10:18:07.844+0000] {standard_task_runner.py:57} INFO - Started process 948 to run task
[2024-09-22T10:18:07.852+0000] {standard_task_runner.py:84} INFO - Running: ['***', 'tasks', 'run', 'flats', 'get_coords', 'manual__2024-09-22T10:17:18.922906+00:00', '--job-id', '1029', '--raw', '--subdir', 'DAGS_FOLDER/flats.py', '--cfg-path', '/tmp/tmp5hy2zlqz']
[2024-09-22T10:18:07.856+0000] {standard_task_runner.py:85} INFO - Job 1029: Subtask get_coords
[2024-09-22T10:18:07.995+0000] {task_command.py:415} INFO - Running <TaskInstance: flats.get_coords manual__2024-09-22T10:17:18.922906+00:00 [running]> on host 1646e3dc8472
[2024-09-22T10:18:08.098+0000] {taskinstance.py:1660} INFO - Exporting env vars: AIRFLOW_CTX_DAG_OWNER='***' AIRFLOW_CTX_DAG_ID='flats' AIRFLOW_CTX_TASK_ID='get_coords' AIRFLOW_CTX_EXECUTION_DATE='2024-09-22T10:17:18.922906+00:00' AIRFLOW_CTX_TRY_NUMBER='1' AIRFLOW_CTX_DAG_RUN_ID='manual__2024-09-22T10:17:18.922906+00:00'
[2024-09-22T10:18:11.858+0000] {taskinstance.py:1935} ERROR - Task failed with exception
Traceback (most recent call last):
  File "/home/airflow/.local/lib/python3.8/site-packages/airflow/operators/python.py", line 192, in execute
    return_value = self.execute_callable()
  File "/home/airflow/.local/lib/python3.8/site-packages/airflow/operators/python.py", line 209, in execute_callable
    return self.python_callable(*self.op_args, **self.op_kwargs)
  File "/opt/airflow/dags/etl.py", line 112, in enrich_coords
    flats_df[['lat', 'lon']] = flats_df['address'].apply(get_coords)
  File "/home/airflow/.local/lib/python3.8/site-packages/pandas/core/frame.py", line 3938, in __setitem__
    self._setitem_array(key, value)
  File "/home/airflow/.local/lib/python3.8/site-packages/pandas/core/frame.py", line 3997, in _setitem_array
    self._iset_not_inplace(key, value)
  File "/home/airflow/.local/lib/python3.8/site-packages/pandas/core/frame.py", line 4016, in _iset_not_inplace
    raise ValueError("Columns must be same length as key")
ValueError: Columns must be same length as key
[2024-09-22T10:18:11.878+0000] {taskinstance.py:1398} INFO - Marking task as FAILED. dag_id=flats, task_id=get_coords, execution_date=20240922T101718, start_date=20240922T101807, end_date=20240922T101811
[2024-09-22T10:18:11.892+0000] {standard_task_runner.py:104} ERROR - Failed to execute job 1029 for task get_coords (Columns must be same length as key; 948)
[2024-09-22T10:18:11.917+0000] {local_task_job_runner.py:228} INFO - Task exited with return code 1
[2024-09-22T10:18:11.941+0000] {taskinstance.py:2776} INFO - 0 downstream tasks scheduled from follow-on schedule check
