[2024-09-26T16:56:35.613+0000] {taskinstance.py:1157} INFO - Dependencies all met for dep_context=non-requeueable deps ti=<TaskInstance: flats.transform_to_dims manual__2024-09-26T16:56:15.166439+00:00 [queued]>
[2024-09-26T16:56:35.624+0000] {taskinstance.py:1157} INFO - Dependencies all met for dep_context=requeueable deps ti=<TaskInstance: flats.transform_to_dims manual__2024-09-26T16:56:15.166439+00:00 [queued]>
[2024-09-26T16:56:35.625+0000] {taskinstance.py:1359} INFO - Starting attempt 1 of 1
[2024-09-26T16:56:35.635+0000] {taskinstance.py:1380} INFO - Executing <Task(PythonOperator): transform_to_dims> on 2024-09-26 16:56:15.166439+00:00
[2024-09-26T16:56:35.639+0000] {standard_task_runner.py:57} INFO - Started process 750 to run task
[2024-09-26T16:56:35.641+0000] {standard_task_runner.py:84} INFO - Running: ['***', 'tasks', 'run', 'flats', 'transform_to_dims', 'manual__2024-09-26T16:56:15.166439+00:00', '--job-id', '27', '--raw', '--subdir', 'DAGS_FOLDER/flats.py', '--cfg-path', '/tmp/tmpn7sjftn_']
[2024-09-26T16:56:35.643+0000] {standard_task_runner.py:85} INFO - Job 27: Subtask transform_to_dims
[2024-09-26T16:56:35.675+0000] {task_command.py:415} INFO - Running <TaskInstance: flats.transform_to_dims manual__2024-09-26T16:56:15.166439+00:00 [running]> on host 5096eb060c49
[2024-09-26T16:56:35.722+0000] {taskinstance.py:1660} INFO - Exporting env vars: AIRFLOW_CTX_DAG_OWNER='***' AIRFLOW_CTX_DAG_ID='flats' AIRFLOW_CTX_TASK_ID='transform_to_dims' AIRFLOW_CTX_EXECUTION_DATE='2024-09-26T16:56:15.166439+00:00' AIRFLOW_CTX_TRY_NUMBER='1' AIRFLOW_CTX_DAG_RUN_ID='manual__2024-09-26T16:56:15.166439+00:00'
[2024-09-26T16:56:35.731+0000] {taskinstance.py:1935} ERROR - Task failed with exception
Traceback (most recent call last):
  File "/home/airflow/.local/lib/python3.8/site-packages/airflow/operators/python.py", line 192, in execute
    return_value = self.execute_callable()
  File "/home/airflow/.local/lib/python3.8/site-packages/airflow/operators/python.py", line 209, in execute_callable
    return self.python_callable(*self.op_args, **self.op_kwargs)
  File "/opt/airflow/dags/etl.py", line 162, in create_flat_dims
    df_to_sql('dim_metro', dim_metro)
  File "/opt/airflow/dags/etl.py", line 145, in df_to_sql
    fl.write(f'INSERT INTO {table_name} ({columns}) VALUES ' + process_values_for_sql(record.values.tolist()) + ';\n')
  File "/opt/airflow/dags/etl.py", line 131, in process_values_for_sql
    return ','.join(value_list)
TypeError: sequence item 1: expected str instance, int found
[2024-09-26T16:56:35.737+0000] {taskinstance.py:1398} INFO - Marking task as FAILED. dag_id=flats, task_id=transform_to_dims, execution_date=20240926T165615, start_date=20240926T165635, end_date=20240926T165635
[2024-09-26T16:56:35.743+0000] {standard_task_runner.py:104} ERROR - Failed to execute job 27 for task transform_to_dims (sequence item 1: expected str instance, int found; 750)
[2024-09-26T16:56:35.781+0000] {local_task_job_runner.py:228} INFO - Task exited with return code 1
[2024-09-26T16:56:35.799+0000] {taskinstance.py:2776} INFO - 0 downstream tasks scheduled from follow-on schedule check
