[2024-09-26T16:56:35.559+0000] {taskinstance.py:1157} INFO - Dependencies all met for dep_context=non-requeueable deps ti=<TaskInstance: flats.transform_to_facts manual__2024-09-26T16:56:15.166439+00:00 [queued]>
[2024-09-26T16:56:35.568+0000] {taskinstance.py:1157} INFO - Dependencies all met for dep_context=requeueable deps ti=<TaskInstance: flats.transform_to_facts manual__2024-09-26T16:56:15.166439+00:00 [queued]>
[2024-09-26T16:56:35.569+0000] {taskinstance.py:1359} INFO - Starting attempt 1 of 1
[2024-09-26T16:56:35.592+0000] {taskinstance.py:1380} INFO - Executing <Task(PythonOperator): transform_to_facts> on 2024-09-26 16:56:15.166439+00:00
[2024-09-26T16:56:35.601+0000] {standard_task_runner.py:57} INFO - Started process 747 to run task
[2024-09-26T16:56:35.605+0000] {standard_task_runner.py:84} INFO - Running: ['***', 'tasks', 'run', 'flats', 'transform_to_facts', 'manual__2024-09-26T16:56:15.166439+00:00', '--job-id', '26', '--raw', '--subdir', 'DAGS_FOLDER/flats.py', '--cfg-path', '/tmp/tmpebq5cp4q']
[2024-09-26T16:56:35.608+0000] {standard_task_runner.py:85} INFO - Job 26: Subtask transform_to_facts
[2024-09-26T16:56:35.649+0000] {task_command.py:415} INFO - Running <TaskInstance: flats.transform_to_facts manual__2024-09-26T16:56:15.166439+00:00 [running]> on host 5096eb060c49
[2024-09-26T16:56:35.695+0000] {taskinstance.py:1660} INFO - Exporting env vars: AIRFLOW_CTX_DAG_OWNER='***' AIRFLOW_CTX_DAG_ID='flats' AIRFLOW_CTX_TASK_ID='transform_to_facts' AIRFLOW_CTX_EXECUTION_DATE='2024-09-26T16:56:15.166439+00:00' AIRFLOW_CTX_TRY_NUMBER='1' AIRFLOW_CTX_DAG_RUN_ID='manual__2024-09-26T16:56:15.166439+00:00'
[2024-09-26T16:56:35.704+0000] {taskinstance.py:1935} ERROR - Task failed with exception
Traceback (most recent call last):
  File "/home/airflow/.local/lib/python3.8/site-packages/airflow/operators/python.py", line 192, in execute
    return_value = self.execute_callable()
  File "/home/airflow/.local/lib/python3.8/site-packages/airflow/operators/python.py", line 209, in execute_callable
    return self.python_callable(*self.op_args, **self.op_kwargs)
  File "/opt/airflow/dags/etl.py", line 215, in create_flat_facts
    df_to_sql('fact_flats', fact_flats)
  File "/opt/airflow/dags/etl.py", line 145, in df_to_sql
    fl.write(f'INSERT INTO {table_name} ({columns}) VALUES ' + process_values_for_sql(record.values.tolist()) + ';\n')
  File "/opt/airflow/dags/etl.py", line 131, in process_values_for_sql
    return ','.join(value_list)
TypeError: sequence item 0: expected str instance, int found
[2024-09-26T16:56:35.710+0000] {taskinstance.py:1398} INFO - Marking task as FAILED. dag_id=flats, task_id=transform_to_facts, execution_date=20240926T165615, start_date=20240926T165635, end_date=20240926T165635
[2024-09-26T16:56:35.719+0000] {standard_task_runner.py:104} ERROR - Failed to execute job 26 for task transform_to_facts (sequence item 0: expected str instance, int found; 747)
[2024-09-26T16:56:35.746+0000] {local_task_job_runner.py:228} INFO - Task exited with return code 1
[2024-09-26T16:56:35.759+0000] {taskinstance.py:2776} INFO - 0 downstream tasks scheduled from follow-on schedule check
