[2024-09-26T17:46:31.708+0000] {taskinstance.py:1157} INFO - Dependencies all met for dep_context=non-requeueable deps ti=<TaskInstance: flats.transform_to_dims manual__2024-09-26T17:46:02.768164+00:00 [queued]>
[2024-09-26T17:46:31.716+0000] {taskinstance.py:1157} INFO - Dependencies all met for dep_context=requeueable deps ti=<TaskInstance: flats.transform_to_dims manual__2024-09-26T17:46:02.768164+00:00 [queued]>
[2024-09-26T17:46:31.716+0000] {taskinstance.py:1359} INFO - Starting attempt 1 of 1
[2024-09-26T17:46:31.735+0000] {taskinstance.py:1380} INFO - Executing <Task(PythonOperator): transform_to_dims> on 2024-09-26 17:46:02.768164+00:00
[2024-09-26T17:46:31.742+0000] {standard_task_runner.py:57} INFO - Started process 1395 to run task
[2024-09-26T17:46:31.746+0000] {standard_task_runner.py:84} INFO - Running: ['***', 'tasks', 'run', 'flats', 'transform_to_dims', 'manual__2024-09-26T17:46:02.768164+00:00', '--job-id', '117', '--raw', '--subdir', 'DAGS_FOLDER/flats.py', '--cfg-path', '/tmp/tmpd4b4k92k']
[2024-09-26T17:46:31.750+0000] {standard_task_runner.py:85} INFO - Job 117: Subtask transform_to_dims
[2024-09-26T17:46:31.827+0000] {task_command.py:415} INFO - Running <TaskInstance: flats.transform_to_dims manual__2024-09-26T17:46:02.768164+00:00 [running]> on host 5096eb060c49
[2024-09-26T17:46:31.934+0000] {taskinstance.py:1660} INFO - Exporting env vars: AIRFLOW_CTX_DAG_OWNER='***' AIRFLOW_CTX_DAG_ID='flats' AIRFLOW_CTX_TASK_ID='transform_to_dims' AIRFLOW_CTX_EXECUTION_DATE='2024-09-26T17:46:02.768164+00:00' AIRFLOW_CTX_TRY_NUMBER='1' AIRFLOW_CTX_DAG_RUN_ID='manual__2024-09-26T17:46:02.768164+00:00'
[2024-09-26T17:46:31.959+0000] {taskinstance.py:1935} ERROR - Task failed with exception
Traceback (most recent call last):
  File "/home/airflow/.local/lib/python3.8/site-packages/pandas/core/computation/scope.py", line 229, in resolve
    return self.scope[key]
  File "/usr/local/lib/python3.8/collections/__init__.py", line 898, in __getitem__
    return self.__missing__(key)            # support subclasses that define __missing__
  File "/usr/local/lib/python3.8/collections/__init__.py", line 890, in __missing__
    raise KeyError(key)
KeyError: 'urls_df'

During handling of the above exception, another exception occurred:

Traceback (most recent call last):
  File "/home/airflow/.local/lib/python3.8/site-packages/pandas/core/computation/scope.py", line 244, in resolve
    return self.temps[key]
KeyError: 'urls_df'

The above exception was the direct cause of the following exception:

Traceback (most recent call last):
  File "/home/airflow/.local/lib/python3.8/site-packages/airflow/operators/python.py", line 192, in execute
    return_value = self.execute_callable()
  File "/home/airflow/.local/lib/python3.8/site-packages/airflow/operators/python.py", line 209, in execute_callable
    return self.python_callable(*self.op_args, **self.op_kwargs)
  File "/opt/airflow/dags/etl.py", line 159, in create_flat_dims
    flats_df.query("url != @urls_df")
  File "/home/airflow/.local/lib/python3.8/site-packages/pandas/core/frame.py", line 4440, in query
    res = self.eval(expr, **kwargs)
  File "/home/airflow/.local/lib/python3.8/site-packages/pandas/core/frame.py", line 4566, in eval
    return _eval(expr, inplace=inplace, **kwargs)
  File "/home/airflow/.local/lib/python3.8/site-packages/pandas/core/computation/eval.py", line 336, in eval
    parsed_expr = Expr(expr, engine=engine, parser=parser, env=env)
  File "/home/airflow/.local/lib/python3.8/site-packages/pandas/core/computation/expr.py", line 809, in __init__
    self.terms = self.parse()
  File "/home/airflow/.local/lib/python3.8/site-packages/pandas/core/computation/expr.py", line 828, in parse
    return self._visitor.visit(self.expr)
  File "/home/airflow/.local/lib/python3.8/site-packages/pandas/core/computation/expr.py", line 415, in visit
    return visitor(node, **kwargs)
  File "/home/airflow/.local/lib/python3.8/site-packages/pandas/core/computation/expr.py", line 421, in visit_Module
    return self.visit(expr, **kwargs)
  File "/home/airflow/.local/lib/python3.8/site-packages/pandas/core/computation/expr.py", line 415, in visit
    return visitor(node, **kwargs)
  File "/home/airflow/.local/lib/python3.8/site-packages/pandas/core/computation/expr.py", line 424, in visit_Expr
    return self.visit(node.value, **kwargs)
  File "/home/airflow/.local/lib/python3.8/site-packages/pandas/core/computation/expr.py", line 415, in visit
    return visitor(node, **kwargs)
  File "/home/airflow/.local/lib/python3.8/site-packages/pandas/core/computation/expr.py", line 719, in visit_Compare
    return self.visit(binop)
  File "/home/airflow/.local/lib/python3.8/site-packages/pandas/core/computation/expr.py", line 415, in visit
    return visitor(node, **kwargs)
  File "/home/airflow/.local/lib/python3.8/site-packages/pandas/core/computation/expr.py", line 535, in visit_BinOp
    op, op_class, left, right = self._maybe_transform_eq_ne(node)
  File "/home/airflow/.local/lib/python3.8/site-packages/pandas/core/computation/expr.py", line 457, in _maybe_transform_eq_ne
    right = self.visit(node.right, side="right")
  File "/home/airflow/.local/lib/python3.8/site-packages/pandas/core/computation/expr.py", line 415, in visit
    return visitor(node, **kwargs)
  File "/home/airflow/.local/lib/python3.8/site-packages/pandas/core/computation/expr.py", line 548, in visit_Name
    return self.term_type(node.id, self.env, **kwargs)
  File "/home/airflow/.local/lib/python3.8/site-packages/pandas/core/computation/ops.py", line 86, in __init__
    self._value = self._resolve_name()
  File "/home/airflow/.local/lib/python3.8/site-packages/pandas/core/computation/ops.py", line 110, in _resolve_name
    res = self.env.resolve(local_name, is_local=is_local)
  File "/home/airflow/.local/lib/python3.8/site-packages/pandas/core/computation/scope.py", line 246, in resolve
    raise UndefinedVariableError(key, is_local) from err
pandas.errors.UndefinedVariableError: local variable 'urls_df' is not defined
[2024-09-26T17:46:31.977+0000] {taskinstance.py:1398} INFO - Marking task as FAILED. dag_id=flats, task_id=transform_to_dims, execution_date=20240926T174602, start_date=20240926T174631, end_date=20240926T174631
[2024-09-26T17:46:32.029+0000] {standard_task_runner.py:104} ERROR - Failed to execute job 117 for task transform_to_dims (local variable 'urls_df' is not defined; 1395)
[2024-09-26T17:46:32.055+0000] {local_task_job_runner.py:228} INFO - Task exited with return code 1
[2024-09-26T17:46:32.080+0000] {taskinstance.py:2776} INFO - 0 downstream tasks scheduled from follow-on schedule check
