[2024-09-26T17:23:40.229+0000] {taskinstance.py:1157} INFO - Dependencies all met for dep_context=non-requeueable deps ti=<TaskInstance: flats.create_facts manual__2024-09-26T17:23:08.043218+00:00 [queued]>
[2024-09-26T17:23:40.241+0000] {taskinstance.py:1157} INFO - Dependencies all met for dep_context=requeueable deps ti=<TaskInstance: flats.create_facts manual__2024-09-26T17:23:08.043218+00:00 [queued]>
[2024-09-26T17:23:40.241+0000] {taskinstance.py:1359} INFO - Starting attempt 1 of 1
[2024-09-26T17:23:40.253+0000] {taskinstance.py:1380} INFO - Executing <Task(PostgresOperator): create_facts> on 2024-09-26 17:23:08.043218+00:00
[2024-09-26T17:23:40.268+0000] {standard_task_runner.py:57} INFO - Started process 828 to run task
[2024-09-26T17:23:40.275+0000] {standard_task_runner.py:84} INFO - Running: ['***', 'tasks', 'run', 'flats', 'create_facts', 'manual__2024-09-26T17:23:08.043218+00:00', '--job-id', '92', '--raw', '--subdir', 'DAGS_FOLDER/flats.py', '--cfg-path', '/tmp/tmp6fuvtlji']
[2024-09-26T17:23:40.279+0000] {standard_task_runner.py:85} INFO - Job 92: Subtask create_facts
[2024-09-26T17:23:40.325+0000] {task_command.py:415} INFO - Running <TaskInstance: flats.create_facts manual__2024-09-26T17:23:08.043218+00:00 [running]> on host 5096eb060c49
[2024-09-26T17:23:40.376+0000] {taskinstance.py:1660} INFO - Exporting env vars: AIRFLOW_CTX_DAG_OWNER='***' AIRFLOW_CTX_DAG_ID='flats' AIRFLOW_CTX_TASK_ID='create_facts' AIRFLOW_CTX_EXECUTION_DATE='2024-09-26T17:23:08.043218+00:00' AIRFLOW_CTX_TRY_NUMBER='1' AIRFLOW_CTX_DAG_RUN_ID='manual__2024-09-26T17:23:08.043218+00:00'
[2024-09-26T17:23:40.377+0000] {sql.py:274} INFO - Executing: INSERT INTO fact_flats (price,processed_dttm,source) VALUES (17830000,'2024-09-26 17:23:32','m2');
INSERT INTO fact_flats (price,processed_dttm,source) VALUES (11479498,'2024-09-26 17:23:32','m2');
[2024-09-26T17:23:40.385+0000] {base.py:73} INFO - Using connection ID 'postgres_conn' for task execution.
[2024-09-26T17:23:40.545+0000] {base.py:73} INFO - Using connection ID 'postgres_conn' for task execution.
[2024-09-26T17:23:40.840+0000] {sql.py:418} INFO - Running statement: INSERT INTO fact_flats (price,processed_dttm,source) VALUES (17830000,'2024-09-26 17:23:32','m2');
INSERT INTO fact_flats (price,processed_dttm,source) VALUES (11479498,'2024-09-26 17:23:32','m2');, parameters: None
[2024-09-26T17:23:40.936+0000] {taskinstance.py:1935} ERROR - Task failed with exception
Traceback (most recent call last):
  File "/home/airflow/.local/lib/python3.8/site-packages/airflow/providers/common/sql/operators/sql.py", line 280, in execute
    output = hook.run(
  File "/home/airflow/.local/lib/python3.8/site-packages/airflow/providers/common/sql/hooks/sql.py", line 392, in run
    self._run_command(cur, sql_statement, parameters)
  File "/home/airflow/.local/lib/python3.8/site-packages/airflow/providers/common/sql/hooks/sql.py", line 423, in _run_command
    cur.execute(sql_statement)
psycopg2.errors.UndefinedTable: relation "fact_flats" does not exist
LINE 1: INSERT INTO fact_flats (price,processed_dttm,source) VALUES ...
                    ^

[2024-09-26T17:23:40.945+0000] {taskinstance.py:1398} INFO - Marking task as FAILED. dag_id=flats, task_id=create_facts, execution_date=20240926T172308, start_date=20240926T172340, end_date=20240926T172340
[2024-09-26T17:23:40.954+0000] {standard_task_runner.py:104} ERROR - Failed to execute job 92 for task create_facts (relation "fact_flats" does not exist
LINE 1: INSERT INTO fact_flats (price,processed_dttm,source) VALUES ...
                    ^
; 828)
[2024-09-26T17:23:40.977+0000] {local_task_job_runner.py:228} INFO - Task exited with return code 1
[2024-09-26T17:23:40.992+0000] {taskinstance.py:2776} INFO - 0 downstream tasks scheduled from follow-on schedule check
