[2024-09-22T10:38:37.036+0000] {taskinstance.py:1157} INFO - Dependencies all met for dep_context=non-requeueable deps ti=<TaskInstance: flats.transform_to_facts manual__2024-09-22T10:37:57.621128+00:00 [queued]>
[2024-09-22T10:38:37.060+0000] {taskinstance.py:1157} INFO - Dependencies all met for dep_context=requeueable deps ti=<TaskInstance: flats.transform_to_facts manual__2024-09-22T10:37:57.621128+00:00 [queued]>
[2024-09-22T10:38:37.061+0000] {taskinstance.py:1359} INFO - Starting attempt 1 of 1
[2024-09-22T10:38:37.092+0000] {taskinstance.py:1380} INFO - Executing <Task(PythonOperator): transform_to_facts> on 2024-09-22 10:37:57.621128+00:00
[2024-09-22T10:38:37.105+0000] {standard_task_runner.py:57} INFO - Started process 1737 to run task
[2024-09-22T10:38:37.109+0000] {standard_task_runner.py:84} INFO - Running: ['***', 'tasks', 'run', 'flats', 'transform_to_facts', 'manual__2024-09-22T10:37:57.621128+00:00', '--job-id', '1078', '--raw', '--subdir', 'DAGS_FOLDER/flats.py', '--cfg-path', '/tmp/tmps938mi3j']
[2024-09-22T10:38:37.112+0000] {standard_task_runner.py:85} INFO - Job 1078: Subtask transform_to_facts
[2024-09-22T10:38:37.214+0000] {task_command.py:415} INFO - Running <TaskInstance: flats.transform_to_facts manual__2024-09-22T10:37:57.621128+00:00 [running]> on host 1646e3dc8472
[2024-09-22T10:38:37.313+0000] {taskinstance.py:1660} INFO - Exporting env vars: AIRFLOW_CTX_DAG_OWNER='***' AIRFLOW_CTX_DAG_ID='flats' AIRFLOW_CTX_TASK_ID='transform_to_facts' AIRFLOW_CTX_EXECUTION_DATE='2024-09-22T10:37:57.621128+00:00' AIRFLOW_CTX_TRY_NUMBER='1' AIRFLOW_CTX_DAG_RUN_ID='manual__2024-09-22T10:37:57.621128+00:00'
[2024-09-22T10:38:37.335+0000] {taskinstance.py:1935} ERROR - Task failed with exception
Traceback (most recent call last):
  File "/home/airflow/.local/lib/python3.8/site-packages/airflow/operators/python.py", line 192, in execute
    return_value = self.execute_callable()
  File "/home/airflow/.local/lib/python3.8/site-packages/airflow/operators/python.py", line 209, in execute_callable
    return self.python_callable(*self.op_args, **self.op_kwargs)
  File "/opt/airflow/dags/etl.py", line 198, in create_flat_facts
    df_to_sql('fact_flats', fact_flats)
  File "/opt/airflow/dags/etl.py", line 127, in df_to_sql
    with open(path, 'a+', encoding='utf8') as fl:
FileNotFoundError: [Errno 2] No such file or directory: 'data/sql/facts.sql'
[2024-09-22T10:38:37.359+0000] {taskinstance.py:1398} INFO - Marking task as FAILED. dag_id=flats, task_id=transform_to_facts, execution_date=20240922T103757, start_date=20240922T103837, end_date=20240922T103837
[2024-09-22T10:38:37.378+0000] {standard_task_runner.py:104} ERROR - Failed to execute job 1078 for task transform_to_facts ([Errno 2] No such file or directory: 'data/sql/facts.sql'; 1737)
[2024-09-22T10:38:37.416+0000] {local_task_job_runner.py:228} INFO - Task exited with return code 1
[2024-09-22T10:38:37.451+0000] {taskinstance.py:2776} INFO - 0 downstream tasks scheduled from follow-on schedule check
