[2024-09-29T07:56:03.340+0000] {taskinstance.py:1157} INFO - Dependencies all met for dep_context=non-requeueable deps ti=<TaskInstance: flats.get_coords manual__2024-09-29T07:55:33.193072+00:00 [queued]>
[2024-09-29T07:56:03.508+0000] {taskinstance.py:1157} INFO - Dependencies all met for dep_context=requeueable deps ti=<TaskInstance: flats.get_coords manual__2024-09-29T07:55:33.193072+00:00 [queued]>
[2024-09-29T07:56:03.515+0000] {taskinstance.py:1359} INFO - Starting attempt 1 of 1
[2024-09-29T07:56:03.872+0000] {taskinstance.py:1380} INFO - Executing <Task(PythonOperator): get_coords> on 2024-09-29 07:55:33.193072+00:00
[2024-09-29T07:56:04.329+0000] {standard_task_runner.py:57} INFO - Started process 7048 to run task
[2024-09-29T07:56:04.635+0000] {standard_task_runner.py:84} INFO - Running: ['***', 'tasks', 'run', 'flats', 'get_coords', 'manual__2024-09-29T07:55:33.193072+00:00', '--job-id', '177', '--raw', '--subdir', 'DAGS_FOLDER/flats.py', '--cfg-path', '/tmp/tmpwc2mrvow']
[2024-09-29T07:56:05.122+0000] {standard_task_runner.py:85} INFO - Job 177: Subtask get_coords
[2024-09-29T07:56:06.776+0000] {task_command.py:415} INFO - Running <TaskInstance: flats.get_coords manual__2024-09-29T07:55:33.193072+00:00 [running]> on host 5096eb060c49
[2024-09-29T07:56:08.023+0000] {taskinstance.py:1660} INFO - Exporting env vars: AIRFLOW_CTX_DAG_OWNER='***' AIRFLOW_CTX_DAG_ID='flats' AIRFLOW_CTX_TASK_ID='get_coords' AIRFLOW_CTX_EXECUTION_DATE='2024-09-29T07:55:33.193072+00:00' AIRFLOW_CTX_TRY_NUMBER='1' AIRFLOW_CTX_DAG_RUN_ID='manual__2024-09-29T07:55:33.193072+00:00'
[2024-09-29T07:56:08.217+0000] {taskinstance.py:1935} ERROR - Task failed with exception
Traceback (most recent call last):
  File "/home/airflow/.local/lib/python3.8/site-packages/airflow/operators/python.py", line 192, in execute
    return_value = self.execute_callable()
  File "/home/airflow/.local/lib/python3.8/site-packages/airflow/operators/python.py", line 209, in execute_callable
    return self.python_callable(*self.op_args, **self.op_kwargs)
  File "/opt/airflow/dags/etl.py", line 117, in enrich_coords
    flats_df = pd.read_csv('data/parser/flats.csv')
  File "/home/airflow/.local/lib/python3.8/site-packages/pandas/io/parsers/readers.py", line 912, in read_csv
    return _read(filepath_or_buffer, kwds)
  File "/home/airflow/.local/lib/python3.8/site-packages/pandas/io/parsers/readers.py", line 577, in _read
    parser = TextFileReader(filepath_or_buffer, **kwds)
  File "/home/airflow/.local/lib/python3.8/site-packages/pandas/io/parsers/readers.py", line 1407, in __init__
    self._engine = self._make_engine(f, self.engine)
  File "/home/airflow/.local/lib/python3.8/site-packages/pandas/io/parsers/readers.py", line 1661, in _make_engine
    self.handles = get_handle(
  File "/home/airflow/.local/lib/python3.8/site-packages/pandas/io/common.py", line 859, in get_handle
    handle = open(
FileNotFoundError: [Errno 2] No such file or directory: 'data/parser/flats.csv'
[2024-09-29T07:56:08.411+0000] {taskinstance.py:1398} INFO - Marking task as FAILED. dag_id=flats, task_id=get_coords, execution_date=20240929T075533, start_date=20240929T075603, end_date=20240929T075608
[2024-09-29T07:56:08.652+0000] {standard_task_runner.py:104} ERROR - Failed to execute job 177 for task get_coords ([Errno 2] No such file or directory: 'data/parser/flats.csv'; 7048)
[2024-09-29T07:56:08.788+0000] {local_task_job_runner.py:228} INFO - Task exited with return code 1
[2024-09-29T07:56:09.528+0000] {taskinstance.py:2776} INFO - 0 downstream tasks scheduled from follow-on schedule check
