[2024-09-29T07:59:04.438+0000] {taskinstance.py:1157} INFO - Dependencies all met for dep_context=non-requeueable deps ti=<TaskInstance: flats.get_coords manual__2024-09-29T07:58:37.633706+00:00 [queued]>
[2024-09-29T07:59:04.477+0000] {taskinstance.py:1157} INFO - Dependencies all met for dep_context=requeueable deps ti=<TaskInstance: flats.get_coords manual__2024-09-29T07:58:37.633706+00:00 [queued]>
[2024-09-29T07:59:04.488+0000] {taskinstance.py:1359} INFO - Starting attempt 1 of 1
[2024-09-29T07:59:04.653+0000] {taskinstance.py:1380} INFO - Executing <Task(PythonOperator): get_coords> on 2024-09-29 07:58:37.633706+00:00
[2024-09-29T07:59:04.689+0000] {standard_task_runner.py:57} INFO - Started process 7207 to run task
[2024-09-29T07:59:04.749+0000] {standard_task_runner.py:84} INFO - Running: ['***', 'tasks', 'run', 'flats', 'get_coords', 'manual__2024-09-29T07:58:37.633706+00:00', '--job-id', '193', '--raw', '--subdir', 'DAGS_FOLDER/flats.py', '--cfg-path', '/tmp/tmp9blk6njp']
[2024-09-29T07:59:04.759+0000] {standard_task_runner.py:85} INFO - Job 193: Subtask get_coords
[2024-09-29T07:59:05.151+0000] {task_command.py:415} INFO - Running <TaskInstance: flats.get_coords manual__2024-09-29T07:58:37.633706+00:00 [running]> on host 5096eb060c49
[2024-09-29T07:59:05.945+0000] {taskinstance.py:1660} INFO - Exporting env vars: AIRFLOW_CTX_DAG_OWNER='***' AIRFLOW_CTX_DAG_ID='flats' AIRFLOW_CTX_TASK_ID='get_coords' AIRFLOW_CTX_EXECUTION_DATE='2024-09-29T07:58:37.633706+00:00' AIRFLOW_CTX_TRY_NUMBER='1' AIRFLOW_CTX_DAG_RUN_ID='manual__2024-09-29T07:58:37.633706+00:00'
[2024-09-29T07:59:05.974+0000] {taskinstance.py:1935} ERROR - Task failed with exception
Traceback (most recent call last):
  File "/home/airflow/.local/lib/python3.8/site-packages/airflow/operators/python.py", line 192, in execute
    return_value = self.execute_callable()
  File "/home/airflow/.local/lib/python3.8/site-packages/airflow/operators/python.py", line 209, in execute_callable
    return self.python_callable(*self.op_args, **self.op_kwargs)
  File "/opt/airflow/dags/etl.py", line 117, in enrich_coords
    flats_df = pd.read_csv('data/parser/flats.csv')
  File "/home/airflow/.local/lib/python3.8/site-packages/pandas/io/parsers/readers.py", line 912, in read_csv
    return _read(filepath_or_buffer, kwds)
  File "/home/airflow/.local/lib/python3.8/site-packages/pandas/io/parsers/readers.py", line 577, in _read
    parser = TextFileReader(filepath_or_buffer, **kwds)
  File "/home/airflow/.local/lib/python3.8/site-packages/pandas/io/parsers/readers.py", line 1407, in __init__
    self._engine = self._make_engine(f, self.engine)
  File "/home/airflow/.local/lib/python3.8/site-packages/pandas/io/parsers/readers.py", line 1661, in _make_engine
    self.handles = get_handle(
  File "/home/airflow/.local/lib/python3.8/site-packages/pandas/io/common.py", line 859, in get_handle
    handle = open(
FileNotFoundError: [Errno 2] No such file or directory: 'data/parser/flats.csv'
[2024-09-29T07:59:06.156+0000] {taskinstance.py:1398} INFO - Marking task as FAILED. dag_id=flats, task_id=get_coords, execution_date=20240929T075837, start_date=20240929T075904, end_date=20240929T075906
[2024-09-29T07:59:06.332+0000] {standard_task_runner.py:104} ERROR - Failed to execute job 193 for task get_coords ([Errno 2] No such file or directory: 'data/parser/flats.csv'; 7207)
[2024-09-29T07:59:06.558+0000] {local_task_job_runner.py:228} INFO - Task exited with return code 1
[2024-09-29T07:59:08.119+0000] {taskinstance.py:2776} INFO - 0 downstream tasks scheduled from follow-on schedule check
