[2024-09-26T16:37:57.902+0000] {taskinstance.py:1157} INFO - Dependencies all met for dep_context=non-requeueable deps ti=<TaskInstance: flats.clear_data manual__2024-09-26T16:37:43.101413+00:00 [queued]>
[2024-09-26T16:37:57.910+0000] {taskinstance.py:1157} INFO - Dependencies all met for dep_context=requeueable deps ti=<TaskInstance: flats.clear_data manual__2024-09-26T16:37:43.101413+00:00 [queued]>
[2024-09-26T16:37:57.910+0000] {taskinstance.py:1359} INFO - Starting attempt 1 of 1
[2024-09-26T16:37:57.925+0000] {taskinstance.py:1380} INFO - Executing <Task(PythonOperator): clear_data> on 2024-09-26 16:37:43.101413+00:00
[2024-09-26T16:37:57.944+0000] {standard_task_runner.py:57} INFO - Started process 243 to run task
[2024-09-26T16:37:57.961+0000] {standard_task_runner.py:84} INFO - Running: ['***', 'tasks', 'run', 'flats', 'clear_data', 'manual__2024-09-26T16:37:43.101413+00:00', '--job-id', '2', '--raw', '--subdir', 'DAGS_FOLDER/flats.py', '--cfg-path', '/tmp/tmpd49ra9tm']
[2024-09-26T16:37:57.997+0000] {standard_task_runner.py:85} INFO - Job 2: Subtask clear_data
[2024-09-26T16:37:58.166+0000] {task_command.py:415} INFO - Running <TaskInstance: flats.clear_data manual__2024-09-26T16:37:43.101413+00:00 [running]> on host 5096eb060c49
[2024-09-26T16:37:58.418+0000] {taskinstance.py:1660} INFO - Exporting env vars: AIRFLOW_CTX_DAG_OWNER='***' AIRFLOW_CTX_DAG_ID='flats' AIRFLOW_CTX_TASK_ID='clear_data' AIRFLOW_CTX_EXECUTION_DATE='2024-09-26T16:37:43.101413+00:00' AIRFLOW_CTX_TRY_NUMBER='1' AIRFLOW_CTX_DAG_RUN_ID='manual__2024-09-26T16:37:43.101413+00:00'
[2024-09-26T16:37:58.430+0000] {taskinstance.py:1935} ERROR - Task failed with exception
Traceback (most recent call last):
  File "/home/airflow/.local/lib/python3.8/site-packages/airflow/operators/python.py", line 192, in execute
    return_value = self.execute_callable()
  File "/home/airflow/.local/lib/python3.8/site-packages/airflow/operators/python.py", line 209, in execute_callable
    return self.python_callable(*self.op_args, **self.op_kwargs)
  File "/opt/airflow/dags/etl.py", line 203, in clear_data
    shutil.rmtree('data/')
  File "/usr/local/lib/python3.8/shutil.py", line 709, in rmtree
    onerror(os.lstat, path, sys.exc_info())
  File "/usr/local/lib/python3.8/shutil.py", line 707, in rmtree
    orig_st = os.lstat(path)
FileNotFoundError: [Errno 2] No such file or directory: 'data/'
[2024-09-26T16:37:58.447+0000] {taskinstance.py:1398} INFO - Marking task as FAILED. dag_id=flats, task_id=clear_data, execution_date=20240926T163743, start_date=20240926T163757, end_date=20240926T163758
[2024-09-26T16:37:58.468+0000] {standard_task_runner.py:104} ERROR - Failed to execute job 2 for task clear_data ([Errno 2] No such file or directory: 'data/'; 243)
[2024-09-26T16:37:58.515+0000] {local_task_job_runner.py:228} INFO - Task exited with return code 1
[2024-09-26T16:37:58.551+0000] {taskinstance.py:2776} INFO - 0 downstream tasks scheduled from follow-on schedule check
