[2024-09-22T10:22:35.963+0000] {taskinstance.py:1157} INFO - Dependencies all met for dep_context=non-requeueable deps ti=<TaskInstance: flats.get_coords manual__2024-09-22T10:21:43.822724+00:00 [queued]>
[2024-09-22T10:22:35.976+0000] {taskinstance.py:1157} INFO - Dependencies all met for dep_context=requeueable deps ti=<TaskInstance: flats.get_coords manual__2024-09-22T10:21:43.822724+00:00 [queued]>
[2024-09-22T10:22:35.977+0000] {taskinstance.py:1359} INFO - Starting attempt 1 of 1
[2024-09-22T10:22:35.995+0000] {taskinstance.py:1380} INFO - Executing <Task(PythonOperator): get_coords> on 2024-09-22 10:21:43.822724+00:00
[2024-09-22T10:22:36.010+0000] {standard_task_runner.py:57} INFO - Started process 1068 to run task
[2024-09-22T10:22:36.019+0000] {standard_task_runner.py:84} INFO - Running: ['***', 'tasks', 'run', 'flats', 'get_coords', 'manual__2024-09-22T10:21:43.822724+00:00', '--job-id', '1035', '--raw', '--subdir', 'DAGS_FOLDER/flats.py', '--cfg-path', '/tmp/tmpfr_j186i']
[2024-09-22T10:22:36.024+0000] {standard_task_runner.py:85} INFO - Job 1035: Subtask get_coords
[2024-09-22T10:22:36.129+0000] {task_command.py:415} INFO - Running <TaskInstance: flats.get_coords manual__2024-09-22T10:21:43.822724+00:00 [running]> on host 1646e3dc8472
[2024-09-22T10:22:36.308+0000] {taskinstance.py:1660} INFO - Exporting env vars: AIRFLOW_CTX_DAG_OWNER='***' AIRFLOW_CTX_DAG_ID='flats' AIRFLOW_CTX_TASK_ID='get_coords' AIRFLOW_CTX_EXECUTION_DATE='2024-09-22T10:21:43.822724+00:00' AIRFLOW_CTX_TRY_NUMBER='1' AIRFLOW_CTX_DAG_RUN_ID='manual__2024-09-22T10:21:43.822724+00:00'
[2024-09-22T10:22:36.320+0000] {taskinstance.py:1935} ERROR - Task failed with exception
Traceback (most recent call last):
  File "/home/airflow/.local/lib/python3.8/site-packages/airflow/operators/python.py", line 192, in execute
    return_value = self.execute_callable()
  File "/home/airflow/.local/lib/python3.8/site-packages/airflow/operators/python.py", line 209, in execute_callable
    return self.python_callable(*self.op_args, **self.op_kwargs)
  File "/opt/airflow/dags/etl.py", line 112, in enrich_coords
    flats_df[['lat', 'lon']] = flats_df['address'].apply(get_coords, axis=1, result_type="expand")
  File "/home/airflow/.local/lib/python3.8/site-packages/pandas/core/series.py", line 4630, in apply
    return SeriesApply(self, func, convert_dtype, args, kwargs).apply()
  File "/home/airflow/.local/lib/python3.8/site-packages/pandas/core/apply.py", line 1025, in apply
    return self.apply_standard()
  File "/home/airflow/.local/lib/python3.8/site-packages/pandas/core/apply.py", line 1076, in apply_standard
    mapped = lib.map_infer(
  File "pandas/_libs/lib.pyx", line 2834, in pandas._libs.lib.map_infer
  File "/home/airflow/.local/lib/python3.8/site-packages/pandas/core/apply.py", line 133, in f
    return func(x, *args, **kwargs)
TypeError: get_coords() got an unexpected keyword argument 'axis'
[2024-09-22T10:22:36.331+0000] {taskinstance.py:1398} INFO - Marking task as FAILED. dag_id=flats, task_id=get_coords, execution_date=20240922T102143, start_date=20240922T102235, end_date=20240922T102236
[2024-09-22T10:22:36.343+0000] {standard_task_runner.py:104} ERROR - Failed to execute job 1035 for task get_coords (get_coords() got an unexpected keyword argument 'axis'; 1068)
[2024-09-22T10:22:36.386+0000] {local_task_job_runner.py:228} INFO - Task exited with return code 1
[2024-09-22T10:22:36.415+0000] {taskinstance.py:2776} INFO - 0 downstream tasks scheduled from follow-on schedule check
