[2024-09-22T10:31:53.527+0000] {taskinstance.py:1157} INFO - Dependencies all met for dep_context=non-requeueable deps ti=<TaskInstance: flats.get_coords manual__2024-09-22T10:30:57.383238+00:00 [queued]>
[2024-09-22T10:31:53.537+0000] {taskinstance.py:1157} INFO - Dependencies all met for dep_context=requeueable deps ti=<TaskInstance: flats.get_coords manual__2024-09-22T10:30:57.383238+00:00 [queued]>
[2024-09-22T10:31:53.537+0000] {taskinstance.py:1359} INFO - Starting attempt 1 of 1
[2024-09-22T10:31:53.550+0000] {taskinstance.py:1380} INFO - Executing <Task(PythonOperator): get_coords> on 2024-09-22 10:30:57.383238+00:00
[2024-09-22T10:31:53.559+0000] {standard_task_runner.py:57} INFO - Started process 1308 to run task
[2024-09-22T10:31:53.565+0000] {standard_task_runner.py:84} INFO - Running: ['***', 'tasks', 'run', 'flats', 'get_coords', 'manual__2024-09-22T10:30:57.383238+00:00', '--job-id', '1047', '--raw', '--subdir', 'DAGS_FOLDER/flats.py', '--cfg-path', '/tmp/tmp_9qe9p2q']
[2024-09-22T10:31:53.568+0000] {standard_task_runner.py:85} INFO - Job 1047: Subtask get_coords
[2024-09-22T10:31:53.613+0000] {task_command.py:415} INFO - Running <TaskInstance: flats.get_coords manual__2024-09-22T10:30:57.383238+00:00 [running]> on host 1646e3dc8472
[2024-09-22T10:31:53.731+0000] {taskinstance.py:1660} INFO - Exporting env vars: AIRFLOW_CTX_DAG_OWNER='***' AIRFLOW_CTX_DAG_ID='flats' AIRFLOW_CTX_TASK_ID='get_coords' AIRFLOW_CTX_EXECUTION_DATE='2024-09-22T10:30:57.383238+00:00' AIRFLOW_CTX_TRY_NUMBER='1' AIRFLOW_CTX_DAG_RUN_ID='manual__2024-09-22T10:30:57.383238+00:00'
[2024-09-22T10:31:57.543+0000] {taskinstance.py:1935} ERROR - Task failed with exception
Traceback (most recent call last):
  File "/home/airflow/.local/lib/python3.8/site-packages/airflow/operators/python.py", line 192, in execute
    return_value = self.execute_callable()
  File "/home/airflow/.local/lib/python3.8/site-packages/airflow/operators/python.py", line 209, in execute_callable
    return self.python_callable(*self.op_args, **self.op_kwargs)
  File "/opt/airflow/dags/etl.py", line 117, in enrich_coords
    flats_df.to_csv('data/enrich/flats.csv')
  File "/home/airflow/.local/lib/python3.8/site-packages/pandas/core/generic.py", line 3772, in to_csv
    return DataFrameRenderer(formatter).to_csv(
  File "/home/airflow/.local/lib/python3.8/site-packages/pandas/io/formats/format.py", line 1186, in to_csv
    csv_formatter.save()
  File "/home/airflow/.local/lib/python3.8/site-packages/pandas/io/formats/csvs.py", line 240, in save
    with get_handle(
  File "/home/airflow/.local/lib/python3.8/site-packages/pandas/io/common.py", line 737, in get_handle
    check_parent_directory(str(handle))
  File "/home/airflow/.local/lib/python3.8/site-packages/pandas/io/common.py", line 600, in check_parent_directory
    raise OSError(rf"Cannot save file into a non-existent directory: '{parent}'")
OSError: Cannot save file into a non-existent directory: 'data/enrich'
[2024-09-22T10:31:57.597+0000] {taskinstance.py:1398} INFO - Marking task as FAILED. dag_id=flats, task_id=get_coords, execution_date=20240922T103057, start_date=20240922T103153, end_date=20240922T103157
[2024-09-22T10:31:57.633+0000] {standard_task_runner.py:104} ERROR - Failed to execute job 1047 for task get_coords (Cannot save file into a non-existent directory: 'data/enrich'; 1308)
[2024-09-22T10:31:57.708+0000] {local_task_job_runner.py:228} INFO - Task exited with return code 1
[2024-09-22T10:31:57.815+0000] {taskinstance.py:2776} INFO - 0 downstream tasks scheduled from follow-on schedule check
