[2024-09-22T10:36:48.320+0000] {taskinstance.py:1157} INFO - Dependencies all met for dep_context=non-requeueable deps ti=<TaskInstance: flats.transform_to_facts manual__2024-09-22T10:36:09.496528+00:00 [queued]>
[2024-09-22T10:36:48.336+0000] {taskinstance.py:1157} INFO - Dependencies all met for dep_context=requeueable deps ti=<TaskInstance: flats.transform_to_facts manual__2024-09-22T10:36:09.496528+00:00 [queued]>
[2024-09-22T10:36:48.337+0000] {taskinstance.py:1359} INFO - Starting attempt 1 of 1
[2024-09-22T10:36:48.354+0000] {taskinstance.py:1380} INFO - Executing <Task(PythonOperator): transform_to_facts> on 2024-09-22 10:36:09.496528+00:00
[2024-09-22T10:36:48.361+0000] {standard_task_runner.py:57} INFO - Started process 1625 to run task
[2024-09-22T10:36:48.365+0000] {standard_task_runner.py:84} INFO - Running: ['***', 'tasks', 'run', 'flats', 'transform_to_facts', 'manual__2024-09-22T10:36:09.496528+00:00', '--job-id', '1071', '--raw', '--subdir', 'DAGS_FOLDER/flats.py', '--cfg-path', '/tmp/tmpz2wes9rn']
[2024-09-22T10:36:48.370+0000] {standard_task_runner.py:85} INFO - Job 1071: Subtask transform_to_facts
[2024-09-22T10:36:48.448+0000] {task_command.py:415} INFO - Running <TaskInstance: flats.transform_to_facts manual__2024-09-22T10:36:09.496528+00:00 [running]> on host 1646e3dc8472
[2024-09-22T10:36:48.586+0000] {taskinstance.py:1660} INFO - Exporting env vars: AIRFLOW_CTX_DAG_OWNER='***' AIRFLOW_CTX_DAG_ID='flats' AIRFLOW_CTX_TASK_ID='transform_to_facts' AIRFLOW_CTX_EXECUTION_DATE='2024-09-22T10:36:09.496528+00:00' AIRFLOW_CTX_TRY_NUMBER='1' AIRFLOW_CTX_DAG_RUN_ID='manual__2024-09-22T10:36:09.496528+00:00'
[2024-09-22T10:36:48.643+0000] {taskinstance.py:1935} ERROR - Task failed with exception
Traceback (most recent call last):
  File "/home/airflow/.local/lib/python3.8/site-packages/airflow/operators/python.py", line 192, in execute
    return_value = self.execute_callable()
  File "/home/airflow/.local/lib/python3.8/site-packages/airflow/operators/python.py", line 209, in execute_callable
    return self.python_callable(*self.op_args, **self.op_kwargs)
  File "/opt/airflow/dags/etl.py", line 198, in create_flat_facts
    df_to_sql('fact_flats', fact_flats)
  File "/opt/airflow/dags/etl.py", line 127, in df_to_sql
    with open(path, 'a', encoding='utf8') as fl:
FileNotFoundError: [Errno 2] No such file or directory: 'data/sql/facts.sql'
[2024-09-22T10:36:48.690+0000] {taskinstance.py:1398} INFO - Marking task as FAILED. dag_id=flats, task_id=transform_to_facts, execution_date=20240922T103609, start_date=20240922T103648, end_date=20240922T103648
[2024-09-22T10:36:48.724+0000] {standard_task_runner.py:104} ERROR - Failed to execute job 1071 for task transform_to_facts ([Errno 2] No such file or directory: 'data/sql/facts.sql'; 1625)
[2024-09-22T10:36:48.785+0000] {local_task_job_runner.py:228} INFO - Task exited with return code 1
[2024-09-22T10:36:48.858+0000] {taskinstance.py:2776} INFO - 0 downstream tasks scheduled from follow-on schedule check
